Workbook
Name printjob: print_history!$A$2:$N$1021
Name Материалы: Материалы!$A$3:$D$9

Sheet Калькулятор печати
A1: Наценка на прибыль | B1: 0.8 | D1: knife-sharpener_NIT-PETG-B3_3h54m.gcode | H1: =VLOOKUP('Калькулятор печати'!D1,printjob,3,0) -> completed
A2: Наценка на развитие | B2: 0.35 | D2: =VLOOKUP('Калькулятор печати'!D1,printjob,12,0) -> 0
A3: Доп. 1 | B3: 100 | D3: Стоимость электроэнергии кВт, ₽ | E3: 7.08 | F3: Время моделирования, час | G3: 0 | H3: Начало печати
A4: Доп. 2 | B4: 0 | D4: Стоимость материала, ₽\кг | E4: =VLOOKUP(G9,Материалы!A2:D90,2,0) -> 869 | F4: Время подготовки, час | G4: 0.0069444444 | H4: =VLOOKUP('Калькулятор печати'!D1,printjob,4,0) -> 46053.629
A5: Доп. 3 | B5: 0 | D5: Стоимость дополнительных материалов, ₽ | E5: 50 | F5: Время печати, час | G5: =VLOOKUP('Калькулятор печати'!D1,printjob,9,0) -> 0.1621412 | H5: Окончание печати
A6: Первоначальная стоимость оборудования, ₽ | B6: 47454 | D6: Стоимость работы оператора, ₽\час | E6: 100 | F6: Время постобработки, час | G6: 0.041666667 | H6: =VLOOKUP('Калькулятор печати'!D1,printjob,5,0) -> 46053.792
A7: Срок полезного использования, лет | B7: 3 | D7: Стоимость работы дизайнера, ₽\час | E7: 600 | F7: Вес изделия, г | G7: =VLOOKUP('Калькулятор печати'!D1,printjob,11,0) -> 134.94029
A8: Годовая норма амортизации | B8: =100%*1/B7 -> 0.33333333 | D8: Стоимость готовой модели, ₽ | E8: 0 | F8: Длина использованного материала, м | G8: =VLOOKUP('Калькулятор печати'!D1,printjob,10,0) -> 45.611101
A9: Ежегодная сумма амортизации, ₽ | B9: =B6*B8 -> 15818 | D9: Потребляемая мощность оборудования, кВт | E9: 0.35 | F9: Название материала | G9: PETG-NIT-W4
A10: Ежемесячная сумма амортизации, ₽ | B10: =B9/12 -> 1318.1667
A11: Ежедневная сумма амортизации, ₽ | B11: =B10/30 -> 43.938889 | D11: Стоимость 3d моделей (дизайн + готовые модели) | E11: =E7*G3*1440/60+E8 -> 0 | F11: Стоимость работ | G11: =E11+E12+E13 -> 116.66667
A12: Амортизация в час (8 часовая смена), ₽ | B12: =B11/8 -> 5.4923611 | D12: Стомость оператора | E12: =E6*G4*1440/60 -> 16.666667
A13: Амортизация в минуту (8 часовая смена), ₽ | B13: =B12/60 -> 0.091539352 | D13: Стоимость постобработки | E13: =E6*G6*1440/60 -> 100
A14: Линейный способ расчёта амортизационной стоимости | D14: Стоимость электроэнергии на печать | E14: =E3*E9*G5*1440/60 -> 9.6428617 | F14: Электроэнергия + пластик + амортизация | G14: =E14+E15+E16 -> 152.08607
D15: Стоимость материала для печати (по весу) | E15: =E4/1000*G7 -> 117.26311
A16: Дата начала эксплуатации | B16: 45611 | D16: Амортизация | E16: =B19*G5+1440/60 -> 25.180099
A17: Дата конца эксплуатации | B17: 46751 | D17: Себестоимость | E17: =E16+E15+E14+E13+E12+E11+E5 -> 318.75274
A18: Рабочих часов за время эксплуатации | B18: =NETWORKDAYS(B16,B17,)*8 -> 6520 | D18: Итоговая стоимость с наценкой + допы | G18: =E17+E17*B1+E17*B2+B3+B4+B5 -> 785.31839
A19: Упрощенная амортизация (за час работы), ₽ | B19: =1/B18*B6 -> 7.2782209
A20: Упрощенная амортизация (за минуту работы), ₽ | B20: =B19/60 -> 0.12130368
A21: Пропорциональный способ расчёта амортизации. Если считать, что принтер способен работать 8 часов в день по 5 дней в неделю. Получается примерно 2000 часов в год. Тогда амортизация за час работы будет 1/2000 в расчёте на один год. Если срок полезного использования 3 года то 1/6000 соответственно.
A23: Серые поля заполняем индивидуально, зеленые расчитываются автоматически. Желтые поля выбираем из списка.

Sheet Материалы
A1: Материал | B1: Стоимость | C1: Дата покупки | D1: Плотность | F1: Плотность по умолчанию 1,27
A2: PETG-NIT-W3 | B2: 965 | C2: 45741 | D2: 1.24 | F2: Плотность вариативная 1,24
A3: PETG-StarPlast-G1 | B3: 916 | C3: 45691 | D3: 1.27
A4: PETG-StarPlast-B1 | B4: 969 | C4: 45691 | D4: 1.27
A5: PETG-NIT-W2 | B5: 790 | C5: 45666 | D5: 1.27
A6: PETG-NIT-W1 | B6: 826 | C6: 45641 | D6: 1.27
A7: PETG-NIT-B1 | B7: 796 | C7: 45641 | D7: 1.27
A8: PETG-123D-B1 | B8: 540 | C8: 45625 | D8: 1.27
A9: PLA-CR-W1 | B9: 0 | C9: 45611 | D9: 1.27
A10: PETG-NIT-B2 | B10: 865 | C10: 45760 | D10: 1.27
A11: PLA-CR-W2 | B11: 1000 | D11: 1.27
A12: PETG-NIT-W4 | B12: 869 | C12: 45990 | D12: 1.27
A13: PETG-NIT-B3 | B13: 694 | C13: 45990 | D13: 1.27
A14: PETG-NIT-BLUE1 | B14: 794 | C14: 45990 | D14: 1.27
A15: PETG-NIT-B4 | B15: 865 | C15: 45757 | D15: 1.27
A16: PETG-NIT-B5 | D16: 1.27

Sheet print_history
A1: filename | B1: type | C1: status | D1: start_time | E1: end_time | F1: print_duration | G1: total_duration | H1: filament_used | I1: Общее время | J1: Длина пластика | K1: Вес пластика | L1: Примечание | M1: Себмстоимость | N1: Цена
A2: seed-planter_1x3_PETG_NIT-W4_0.20mm Standard @Creality K1C my_2h4m.gcode | B2: job | C2: completed | D2: 46090.742 | E2: 46090.826 | F2: 6829 | G2: 7209 | H2: 26141.233 | I2: =G2/86400 -> 0.0834375 | J2: =H2/1000 -> 26.141233 | K2: =1.23*PI()*(1.75/2)^2*H2/1000 -> 77.338752
A3: крепление крючка_PETG_NIT-W4_0.12mm Fine_5m26s.gcode | B3: job | C3: completed | D3: 46090.708 | E3: 46090.716 | F3: 360 | G3: 687 | H3: 571.255 | I3: =G3/86400 -> 0.0079513889 | J3: =H3/1000 -> 0.571255 | K3: =1.23*PI()*(1.75/2)^2*H3/1000 -> 1.690056
A4: self-watering-pot-pot-100-x-100-x-100-mm_PETG_NIT-B4_0.20mm Standard 100 quality_3h8m.gcode | B4: job | C4: completed | D4: 46082.525 | E4: 46082.659 | F4: 11274 | G4: 11611 | H4: 28900.368 | I4: =G4/86400 -> 0.13438657 | J4: =H4/1000 -> 28.900368 | K4: =1.23*PI()*(1.75/2)^2*H4/1000 -> 85.501644
A5: self-watering-pot-base-100-x-100-mm_PETG_NIT-B4_0.20mm Standard 150_1h34m.gcode | B5: job | C5: completed | D5: 46082.442 | E5: 46082.506 | F5: 5086 | G5: 5486 | H5: 18878.802 | I5: =G5/86400 -> 0.06349537 | J5: =H5/1000 -> 18.878802 | K5: =1.23*PI()*(1.75/2)^2*H5/1000 -> 55.852874
A6: Bottom - 0.4 PETG-PC_PETG_NIT-B3_0.20mm Standard 150_31m51s.gcode | B6: job | C6: completed | D6: 46081.938 | E6: 46081.966 | F6: 1976 | G6: 2401 | H6: 3809.439 | I6: =G6/86400 -> 0.027789352 | J6: =H6/1000 -> 3.809439 | K6: =1.23*PI()*(1.75/2)^2*H6/1000 -> 11.270213
A7: adapter_PETG_NIT-B3_0.20mm Standard 120_19m48s.gcode | B7: job | C7: completed | D7: 46081.906 | E7: 46081.924 | F7: 1183 | G7: 1539 | H7: 3049.159 | I7: =G7/86400 -> 0.0178125 | J7: =H7/1000 -> 3.049159 | K7: =1.23*PI()*(1.75/2)^2*H7/1000 -> 9.0209269
A8: stone_holder_wusthof_PETG_NIT-B3_0.20mm Standard 120_53m10s.gcode | B8: job | C8: completed | D8: 46061.467 | E8: 46061.506 | F8: 2998 | G8: 3362 | H8: 6280.199 | I8: =G8/86400 -> 0.038912037 | J8: =H8/1000 -> 6.280199 | K8: =1.23*PI()*(1.75/2)^2*H8/1000 -> 18.579948
A9: stone_holder_wusthof_NIT-PETG-B3_42m56s.gcode | B9: job | C9: completed | D9: 46054.522 | E9: 46054.554 | F9: 2460 | G9: 2779 | H9: 5948.623 | I9: =G9/86400 -> 0.032164352 | J9: =H9/1000 -> 5.948623 | K9: =1.23*PI()*(1.75/2)^2*H9/1000 -> 17.598982
A10: knife-sharpener_NIT-PETG-B3_3h54m.gcode | B10: job | C10: completed | D10: 46053.629 | E10: 46053.792 | F10: 13564 | G10: 14009 | H10: 45611.101 | I10: =G10/86400 -> 0.1621412 | J10: =H10/1000 -> 45.611101 | K10: =1.23*PI()*(1.75/2)^2*H10/1000 -> 134.94029
A11: circle_75_PETG_35m28s.gcode | B11: job | C11: completed | D11: 46034.915 | E11: 46034.945 | F11: 2165 | G11: 2633 | H11: 9113.253 | I11: =G11/86400 -> 0.030474537 | J11: =H11/1000 -> 9.113253 | K11: =1.23*PI()*(1.75/2)^2*H11/1000 -> 26.961529
A12: gridfinity-pult_PETG_NIT-B3_0.20mm Standard 120_38m39s.gcode | B12: job | C12: completed | D12: 46029.426 | E12: 46029.456 | F12: 2194 | G12: 2512 | H12: 6056.881 | I12: =G12/86400 -> 0.029074074 | J12: =H12/1000 -> 6.056881 | K12: =1.23*PI()*(1.75/2)^2*H12/1000 -> 17.919262
A13: gridfinity-2x1-usb-c-microsd-v7_PETG_NIT-B3_0.20mm Standard 120_1h5m.gcode | B13: job | C13: completed | D13: 46027.881 | E13: 46027.931 | F13: 3937 | G13: 4264 | H13: 9101.044 | I13: =G13/86400 -> 0.049351852 | J13: =H13/1000 -> 9.101044 | K13: =1.23*PI()*(1.75/2)^2*H13/1000 -> 26.925409
... A103: Duct_PETG_STARPLAST_0.16mm Optimal 150_2h50m.gcode | B103: job | C103: completed | D103: 45762.817 | E103: 45762.941 | F103: 10266 | G103: 10683 | H103: 22027.653 | I103: =G103/86400 -> 0.12364583 | J103: =H103/1000 -> 22.027653 | K103: =1.23*PI()*(1.75/2)^2*H103/1000 -> 65.168739
A104: 14-khz-whistle_PETG_STARPLAST_0.16mm Optimal 150_21m4s.gcode | B104: job | C104: completed | D104: 45760.742 | E104: 45760.76 | F104: 1300 | G104: 1618 | H104: 1707.364 | I104: =G104/86400 -> 0.018726852 | J104: =H104/1000 -> 1.707364 | K104: =1.23*PI()*(1.75/2)^2*H104/1000 -> 5.0512308 | L104: свисток на 14 кГц
A105: pressure_advance_test_PETG_STARPLAST_0.16mm Optimal 150_6m56s.gcode | B105: job | C105: completed | D105: 45760.728 | E105: 45760.738 | F105: 454 | G105: 887 | H105: 484.901 | I105: =G105/86400 -> 0.010266204 | J105: =H105/1000 -> 0.484901 | K105: =1.23*PI()*(1.75/2)^2*H105/1000 -> 1.434578 | L105: тест
A106: 38.4mm1cyl_valve_PETG_STARPLAST_0.16mm Optimal 150_48m19s.gcode | B106: job | C106: completed | D106: 45760.686 | E106: 45760.724 | F106: 2979 | G106: 3303 | H106: 4749.244 | I106: =G106/86400 -> 0.038229167 | J106: =H106/1000 -> 4.749244 | K106: =1.23*PI()*(1.75/2)^2*H106/1000 -> 14.050623 | L106: лего перегородки 3 шт
A107: Base_PETG_STARPLAST_0.16mm Optimal 150_2h5m.gcode | B107: job | C107: completed | D107: 45760.519 | E107: 45760.611 | F107: 7563 | G107: 7938 | H107: 12215.724 | I107: =G107/86400 -> 0.091875 | J107: =H107/1000 -> 12.215724 | K107: =1.23*PI()*(1.75/2)^2*H107/1000 -> 36.140179 | L107: база на углесос удачный
A108: Base_PETG_STARPLAST_0.16mm Optimal 150_2h3m.gcode | B108: job | C108: completed | D108: 45760.387 | E108: 45760.496 | F108: 9073 | G108: 9436 | H108: 14540.585 | I108: =G108/86400 -> 0.10921296 | J108: =H108/1000 -> 14.540585 | K108: =1.23*PI()*(1.75/2)^2*H108/1000 -> 43.018273 | L108: база на углесос косячный
A109: Cover_PETG_STARPLAST_0.16mm Optimal 150_1h6m.gcode | B109: job | C109: completed | D109: 45759.902 | E109: 45759.953 | F109: 3996 | G109: 4433 | H109: 9320.64 | I109: =G109/86400 -> 0.05130787 | J109: =H109/1000 -> 9.32064 | K109: =1.23*PI()*(1.75/2)^2*H109/1000 -> 27.575083 | L109: крышка на углесос
A110: Cover_PETG_STARPLAST_0.16mm Optimal 150_1h6m.gcode | B110: job | C110: klippy_disconnect | D110: 45759.9 | E110: 45759.901 | F110: 0 | G110: 26 | H110: 0 | I110: =G110/86400 -> 0.00030092593 | J110: =H110/1000 -> 0 | K110: =1.23*PI()*(1.75/2)^2*H110/1000 -> 0
A111: 38.4mm1cyl_valve_PETG_STARPLAST_0.16mm Optimal 150_15m18s.gcode | B111: job | C111: completed | D111: 45759.878 | E111: 45759.892 | F111: 978 | G111: 1285 | H111: 1606.007 | I111: =G111/86400 -> 0.014872685 | J111: =H111/1000 -> 1.606007 | K111: =1.23*PI()*(1.75/2)^2*H111/1000 -> 4.7513664 | L111: лего перегородка 1 шт
A112: OrcaCube_PETG_StarPlast-B1_0.20mm Standard 120_39m19s.gcode | B112: job | C112: completed | D112: 45759.758 | E112: 45759.787 | F112: 2254 | G112: 2582 | H112: 4218.788 | I112: =G112/86400 -> 0.029884259 | J112: =H112/1000 -> 4.218788 | K112: =1.23*PI()*(1.75/2)^2*H112/1000 -> 12.48127 | L112: тест орка кубик
A113: Base_PETG_STARPLAST_0.16mm Optimal 150_1h58m.gcode | B113: job | C113: cancelled | D113: 45759.581 | E113: 45759.63 | F113: 3792 | G113: 4187 | H113: 9419.558 | I113: =G113/86400 -> 0.048460648 | J113: =H113/1000 -> 9.419558 | K113: =1.23*PI()*(1.75/2)^2*H113/1000 -> 27.867731 | L113: база на углесос косячный
A114: K1_best_5015_blower_remix_2025_PETG_STARPLAST_0.16mm Optimal 150_2h14m.gcode | B114: job | C114: completed | D114: 45759.409 | E114: 45759.505 | F114: 7939 | G114: 8301 | H114: 6963.853 | I114: =G114/86400 -> 0.096076389 | J114: =H114/1000 -> 6.963853 | K114: =1.23*PI()*(1.75/2)^2*H114/1000 -> 20.602536 | L114: держатель дуйки 5015 ремикс 2025
A115: Base cover_PETG_STARPLAST_0.16mm Optimal 150_38m58s.gcode | B115: job | C115: completed | D115: 45758.927 | E115: 45758.958 | F115: 2335 | G115: 2708 | H115: 5274.29 | I115: =G115/86400 -> 0.031342593 | J115: =H115/1000 -> 5.27429 | K115: =1.23*PI()*(1.75/2)^2*H115/1000 -> 15.60397 | L115: крышка на базу углесоса
A116: Base_PETG_STARPLAST_0.16mm Optimal 150_1h45m.gcode | B116: job | C116: cancelled | D116: 45758.76 | E116: 45758.804 | F116: 3322 | G116: 3760 | H116: 9187.06 | I116: =G116/86400 -> 0.043518519 | J116: =H116/1000 -> 9.18706 | K116: =1.23*PI()*(1.75/2)^2*H116/1000 -> 27.179887 | L116: база на углесос косячный
A117: peglock_board_attachment_PETG_STARPLAST_0.20mm Standard 150_14m2s.gcode | B117: job | C117: completed | D117: 45757.946 | E117: 45757.959 | F117: 833 | G117: 1119 | H117: 1339.844 | I117: =G117/86400 -> 0.012951389 | J117: =H117/1000 -> 1.339844 | K117: =1.23*PI()*(1.75/2)^2*H117/1000 -> 3.9639241 | L117: пеглок 2 шт
A118: temperature_tower_PETG_STARPLAST_0.20mm Standard 150_45m24s.gcode | B118: job | C118: completed | D118: 45757.887 | E118: 45757.923 | F118: 2819 | G118: 3123 | H118: 2946.269 | I118: =G118/86400 -> 0.036145833 | J118: =H118/1000 -> 2.946269 | K118: =1.23*PI()*(1.75/2)^2*H118/1000 -> 8.7165271 | L118: тест
A119: Base_PETG_STARPLAST_0.20mm Standard 150_1h33m.gcode | B119: job | C119: completed | D119: 45757.813 | E119: 45757.878 | F119: 5197 | G119: 5576 | H119: 14250.53 | I119: =G119/86400 -> 0.064537037 | J119: =H119/1000 -> 14.25053 | K119: =1.23*PI()*(1.75/2)^2*H119/1000 -> 42.160146 | L119: база на углесос косячный
A120: 14-khz-whistle_PETG_STARPLAST_0.16mm Optimal 150_18m25s.gcode | B120: job | C120: completed | D120: 45756.903 | E120: 45756.92 | F120: 1130 | G120: 1460 | H120: 2272.09 | I120: =G120/86400 -> 0.016898148 | J120: =H120/1000 -> 2.27209 | K120: =1.23*PI()*(1.75/2)^2*H120/1000 -> 6.7219708 | L120: свисток на 14 кГц косячный
A121: gridfinity-standalone-base-4x4_PETG_STARPLAST_0.20mm Standard 150_1h47m.gcode | B121: job | C121: completed | D121: 45756.792 | E121: 45756.867 | F121: 6022 | G121: 6481 | H121: 16394.202 | I121: =G121/86400 -> 0.075011574 | J121: =H121/1000 -> 16.394202 | K121: =1.23*PI()*(1.75/2)^2*H121/1000 -> 48.502193 | L121: база гридфинити 4×4 настольная
A122: Pegboard gridfinity 1x3 shorter_PETG_STARPLAST_0.16mm Optimal 230_1h22m.gcode | B122: job | C122: completed | D122: 45754.878 | E122: 45754.938 | F122: 4841 | G122: 5204 | H122: 8585.841 | I122: =G122/86400 -> 0.060231481 | J122: =H122/1000 -> 8.585841 | K122: =1.23*PI()*(1.75/2)^2*H122/1000 -> 25.401182 | L122: гридфинити держатель на пегборду 1×3
... A141: Planter _PETG_STARPLAST_0.20mm Standard 150_1h46m.gcode | B141: job | C141: completed | D141: 45739.784 | E141: 45739.862 | F141: 6398 | G141: 6734 | H141: 22359.01 | I141: =G141/86400 -> 0.077939815 | J141: =H141/1000 -> 22.35901 | K141: =1.23*PI()*(1.75/2)^2*H141/1000 -> 66.149057 | L141: горшочек
A142: cable_clips_PETG_STARPLAST_0.16mm Optimal_1h7m.gcode | B142: job | C142: completed | D142: 45738.899 | E142: 45738.946 | F142: 3678 | G142: 4031 | H142: 8428.36 | I142: =G142/86400 -> 0.046655093 | J142: =H142/1000 -> 8.42836 | K142: =1.23*PI()*(1.75/2)^2*H142/1000 -> 24.935275
A143: cable_clip_14mm_PETG_STARPLAST_0.16mm Optimal_6m39s.gcode | B143: job | C143: completed | D143: 45738.878 | E143: 45738.887 | F143: 362 | G143: 692 | H143: 682.517 | I143: =G143/86400 -> 0.0080092593 | J143: =H143/1000 -> 0.682517 | K143: =1.23*PI()*(1.75/2)^2*H143/1000 -> 2.0192243
A144: SpeedTestStructure_PETG_STARPLAST_0.20mm Standard 150_14m7s.gcode | B144: job | C144: completed | D144: 45738.773 | E144: 45738.787 | F144: 879 | G144: 1302 | H144: 3627.235 | I144: =G144/86400 -> 0.015069444 | J144: =H144/1000 -> 3.627235 | K144: =1.23*PI()*(1.75/2)^2*H144/1000 -> 10.731163
A145: VFA_PETG_STARPLAST_0.20mm Standard_53m24s.gcode | B145: job | C145: completed | D145: 45738.692 | E145: 45738.733 | F145: 3148 | G145: 3525 | H145: 9143.981 | I145: =G145/86400 -> 0.040798611 | J145: =H145/1000 -> 9.143981 | K145: =1.23*PI()*(1.75/2)^2*H145/1000 -> 27.052438
A146: OrcaToleranceTest_PETG_STARPLAST_0.16mm Optimal_10m32s.gcode | B146: job | C146: completed | D146: 45733.942 | E146: 45733.953 | F146: 655 | G146: 970 | H146: 1015.998 | I146: =G146/86400 -> 0.011226852 | J146: =H146/1000 -> 1.015998 | K146: =1.23*PI()*(1.75/2)^2*H146/1000 -> 3.0058267
A147: pressure_advance_test_PETG_STARPLAST_0.16mm Optimal_3m21s.gcode | B147: job | C147: completed | D147: 45733.931 | E147: 45733.938 | F147: 233 | G147: 656 | H147: 256.732 | I147: =G147/86400 -> 0.0075925926 | J147: =H147/1000 -> 0.256732 | K147: =1.23*PI()*(1.75/2)^2*H147/1000 -> 0.75954078
...
